Workbook

Sheet Original Articles
A1: CSV Row | B1: Article ID | C1: Ticker | D1: Title | E1: Snippet | F1: Embedded Text (format_news_content) | G1: Embedding (all-MiniLM-L6-v2, normalized)
A2: 1 | B2: 99d3c240-a69d-471e-9754-bd53d542c01f | C2: CBA.AX | D2: Banks warn AI shopping agents could increase risk of scams, fraud and data privacy breaches | E2: A coalition of global banks says agentic AI tools that make purchases on behalf of consumers could expose card details and weaken payment security. | F2: Banks warn AI shopping agents could increase risk of scams, fraud and data privacy breaches - A coalition of global banks says agentic AI tools that make purchases on behalf of consumers could expose card details and weaken payment security. | G2: [-0.05099, 0.004412, -0.082482, -0.00913, 0.029339, 0.028803, 0.101072, 0.00717, -0.007238, -0.039414, 0.014977, 0.009957, 0.065063, -0.006501, 0.091146, -0.010006, 0.065569, 0.027633, -0.030093, 0.03226, 0.012441, -0.015713, -0.057893, 0.010292, -0.081095, -0.000567, 0.019981, -0.057118, -0.066315, 0.0045, 0.0651, 0.052246, 0.077569, 0.026662, 0.041609, -0.050985, -0.05682, 7e-06, 0.042773, -0.028856, -0.014416, -0.063962, -0.038921, -0.021972, 0.051355, 0.032223, 0.000866, 0.041038, -0.017591, 0.053122, -0.104528, -0.013055, 0.040316, -0.03307, -0.122557, -0.025499, 0.021914, -0.039072, -0.006576, -0.043162, 0.052584, -0.042594, 0.084833, 0.058371, 0.033079, 0.063096, -0.090461, -0.013011, -0.02028, -0.026112, 0.066991, -0.067103, -0.016, -0.027572, 0.054057, 0.035637, 0.028802, -0.027993, 0.073102, -0.045159, -0.063143, -0.068805, 0.028951, 0.043257, -0.037864, 0.038604, 0.024515, -0.049827, 0.021122, -0.099248, 0.062209, -0.021909, 0.038176, -0.020397, 0.088372, -0.025704, -0.090235, -0.093952, -0.010388, 0.009677, -0.000255, 0.073757, -0.000626, 0.042575, 0.0067, 0.008111, 0.088226, -0.020191, 0.059429, -0.019434, -0.033579, -0.014326, 0.075382, -0.04656, 0.068378, 0.035451, -0.050109, 0.117464, 0.020812, 0.040952, 0.034025, 0.028701, -0.016637, 0.025626, 0.040662, 0.083395, -0.036628, 0.0, -0.054546, 0.024338, -0.000492, -0.068857, 0.039155, -0.031431, -0.013725, -0.029859, -0.008222, 0.066394, -0.023904, 0.021657, -0.009874, 0.082266, 0.030508, 0.052272, -0.037285, 0.049946, 0.082813, 0.020965, 0.064095, -0.107464, 0.073249, -0.011519, 0.066541, 0.020555, -0.031472, -0.035378, 0.174533, -0.008025, -0.016096, 0.01118, 0.018817, 0.056434, -0.067001, 0.094482, -0.079703, -0.008869, 0.006112, 0.049279, -0.038548, 0.044344, 0.105616, -0.027287, -0.033099, 0.035546, -0.014505, -0.030543, -0.03355, 0.012601, -0.092761, 0.032837, -0.013977, -0.03536, 0.006683, -0.088972, 0.039513, 0.005256, 0.01559, -0.085081, -0.073783, -0.087139, -0.011515, 0.020903, -0.054392, 0.012227, 0.086426, -0.014613, -0.02314, 0.041929, -0.055382, 0.069087, 0.026036, -0.001456, -0.09131, -0.033181, -0.009703, -0.005643, 0.049566, -0.058714, -0.06178, -0.045808, 0.05009, 0.049834, -0.026879, 0.046048, -0.021584, -0.043527, 0.000112, -0.019484, -0.042224, -0.015445, -0.023148, 0.078251, 0.012675, -0.0, -0.104166, -0.089025, -0.083373, 0.034755, -0.076815, -0.037809, -0.044349, -0.009624, 0.068169, -0.021879, -0.029096, 0.072552, 0.024484, -0.020722, 0.043729, -0.035542, 0.035032, 0.003899, 0.054166, -0.07354, 0.045652, 0.047305, -0.023853, -0.022713, 0.049573, 0.021564, -0.032365, 0.010826, 0.03973, -0.024102, 0.002156, -0.003416, -0.01151, 0.080337, 0.001068, 0.027009, 0.019146, 0.040513, 0.010143, 0.039225, 0.013669, -0.008982, -0.077711, -0.042164, -0.006047, -0.035713, 0.027992, 0.049739, 0.055225, -0.01387, -0.06409, -0.002908, -0.012435, -0.054806, -0.127222, 0.105058, 0.096047, 0.009248, -0.005084, -0.012462, -0.06232, 0.020445, 0.023395, -0.020478, -0.026781, 0.001754, -0.034308, 0.024179, 0.092956, -0.051956, 0.066057, -0.057776, -0.041301, 0.095131, 0.002462, -0.009359, -0.016876, -0.047969, -0.01358, -0.053396, -0.003545, -0.017476, 0.073317, 0.029122, 0.037275, 7.7e-05, -0.021865, -0.064412, -0.022443, -0.046687, -0.062153, 0.000644, 0.002986, 0.015992, -0.160437, -0.0, 0.025506, -0.034105, 0.086399, 0.03195, 0.044405, -0.059996, -0.034972, 0.033038, -0.105735, -0.046228, 0.0641, -0.031094, -0.033533, -0.021565, 0.06694, 0.031769, 0.022583, -0.058074, -0.027038, -0.051849, 0.042193, -0.011359, 0.012225, -0.053224, -0.017197, -0.026852, 0.036719, 0.046726, -0.017839, 0.071291, -0.052169, 0.002605, 0.107915, 0.035795, 0.093559, 0.035945, 0.028255, -0.053848, -0.060115, -0.004305, 0.003053, -0.054078, -0.000731, -0.061221, 0.046472, -0.063913, -0.013961, -0.112885, 0.137237, -0.020816, -0.079606, -0.008166, 0.049255, 0.114267, 0.07705, -0.078099, 0.023855, -0.070955, 0.109279, 0.040944, -0.006684, 0.010301, 0.031, -0.094949]
A3: 2 | B3: b1b83951-4c53-41ff-a55f-9a52d2b6570d | C3: CBA.AX | D3: Banks warn AI shopping agents outpace fraud protections | E3: NatWest, Bank of America, and four other banks say consumers risk scams and data breaches as AI commerce tools advance faster than industry safeguards | F3: Banks warn AI shopping agents outpace fraud protections - NatWest, Bank of America, and four other banks say consumers risk scams and data breaches as AI commerce tools advance faster than industry safeguards | G3: [-0.014682, -0.07234, -0.054475, -0.0042, 0.091505, 0.025968, 0.079649, -0.013261, 0.008069, -0.032533, 0.021076, 0.042247, 0.083079, -0.044598, 0.066689, 0.012786, 0.033938, 0.005379, -0.034333, -0.009791, 0.026608, -0.011332, -0.045449, 0.048694, -0.056949, -0.008387, 0.012224, -0.063886, -0.085033, -0.040651, -0.000701, 0.01526, 0.051502, 0.016273, 0.044642, -0.044168, -0.001241, -0.009924, 0.072087, -0.07836, 0.017584, -0.062724, -0.021652, 0.007999, 0.047123, 0.05284, 0.002984, 0.022436, -0.003995, 0.042775, -0.077769, -0.029279, 0.033146, 0.004387, -0.106084, 0.012608, 0.031972, 0.011636, 0.0018, 0.008478, 0.10695, -0.041439, 0.069278, 0.050113, 0.028973, 0.068716, -0.115218, 0.008757, -0.03658, -0.007114, 0.062306, -0.117635, -0.076255, 0.016987, 0.020302, 0.054841, 0.021542, -0.022179, 0.090914, -0.03083, -0.028192, -0.071816, -0.007991, 0.046258, -0.010754, 0.002887, -0.009926, -0.044687, 0.013775, -0.080033, 0.063373, -0.047075, 0.042719, 0.011706, 0.055678, -0.082157, -0.070915, -0.047362, 0.03023, -0.014906, 0.025387, 0.097655, -0.03198, 0.026616, -0.013732, -0.034767, 0.049769, -0.019794, 0.062153, 0.032335, 0.023819, 0.021401, 0.104675, 0.006455, 0.048386, 0.050984, -0.071615, 0.094216, 0.039845, 0.04164, 0.01236, 0.10067, 0.003205, -0.01093, 0.030131, 0.045112, -0.03338, 0.0, -0.067817, 0.0302, 0.00518, -0.074722, 0.028347, -0.021197, -0.046504, 0.019061, -0.002501, 0.111221, -0.084189, 0.001976, -0.005517, 0.024142, 0.020884, 0.066327, 0.020269, 0.044258, 0.03045, -0.006614, 0.066167, -0.08323, 0.054544, 0.030425, 0.063573, -0.021464, -0.039843, 0.003477, 0.144367, 0.009627, -0.012916, 0.024691, 0.012457, 0.031795, -0.047305, 0.069026, -0.066962, -0.035555, -0.025933, 0.035944, -0.078983, 0.06349, 0.071547, 0.04146, -0.006889, 0.023129, -0.023316, -0.023302, -0.029594, 0.033954, -0.117273, 0.050591, -0.027656, -0.007776, 0.015747, -0.071559, 0.040774, -0.000371, 0.042934, -0.002683, -0.0183, -0.045794, -0.053187, 0.014631, -0.061277, 0.021235, 0.073244, -0.003916, -0.057869, 0.03633, -0.0053, 0.03825, 0.004742, 0.011284, -0.103126, -0.069024, -0.012102, -0.018272, 0.021264, -0.107209, -0.035144, -0.054191, 0.102573, 0.057985, -0.052416, 0.007263, -0.016079, -0.023021, 0.003788, -0.000416, -0.081468, -0.019793, 0.053786, 0.06766, -0.02576, -0.0, -0.104301, -0.079946, -0.038072, 0.029913, -0.054901, -0.031646, -0.051896, -0.002555, 0.052064, -0.040671, -0.059612, 0.052462, 0.069309, 0.016511, 0.024392, -0.039951, 0.087157, -0.004604, 0.010604, -0.08797, 0.129662, 0.051487, -0.001961, -0.017384, -0.015924, 0.025813, -0.042515, 0.04171, 0.057651, -0.009072, 0.003138, 0.020354, 0.006395, 0.109905, -0.035543, -0.046641, 0.035064, 0.006737, -0.015815, 0.029449, 0.020024, 0.032935, -0.111043, -0.051666, -0.000581, -0.01218, 0.013732, 0.023595, 0.062445, 0.009036, -0.052202, -0.026131, -0.008636, -0.014548, -0.116487, 0.077669, 0.093303, -0.000328, -0.014678, 0.014919, -0.041454, 0.014801, 0.042395, -0.005187, -0.012171, -0.008358, -0.007644, 0.06363, 0.071983, -0.076715, 0.026447, -0.055226, -0.057355, 0.06936, -0.062141, -0.001094, -0.035778, -0.063426, -0.032451, -0.04084, 0.03048, -0.040764, 0.093319, 0.073305, 0.055694, 0.047797, -0.000252, -0.078255, -0.029191, -0.042534, -0.078872, -0.050017, -0.033068, 0.019379, -0.098648, -0.0, 0.027222, -0.040245, 0.090737, 0.021558, 0.078811, -0.04827, -0.017831, 0.085447, -0.074698, -0.079585, 0.018362, -0.05194, -0.048252, -0.018593, 0.060891, 0.015276, -0.014853, -0.029133, -0.016393, -0.011511, 0.034712, 0.017073, -0.009595, -0.074804, -0.019317, -0.032944, 0.015718, 0.090807, -0.002497, 0.030578, -0.084149, -0.022018, 0.117919, -0.018006, 0.03045, 0.031125, 0.068317, -0.010896, -0.03126, -0.002592, -0.034444, -0.073048, -0.012392, -0.041141, 0.036489, -0.088281, -0.026767, -0.038617, 0.150308, -0.007221, -0.042086, -0.053598, 0.056777, 0.106801, 0.097661, -0.080815, -0.025991, -0.089444, 0.041097, 0.03388, 0.005198, -0.070446, 0.059856, -0.092247]
A4: 3 | B4: d1b0bef8-6caa-4a64-88c9-3a0aa08b588b | C4: CBA.AX | D4: Interview: CBA AI chief on scaling A$400m in AI value with humans in loop | E4: Ranil Boteju, the chief AI officer at CBA, tells Satarupa Bhowmik how 80% of the bank's engineers use AI agents to triple code output and resolve over 15,000 security issues. | F4: Interview: CBA AI chief on scaling A$400m in AI value with humans in loop - Ranil Boteju, the chief AI officer at CBA, tells Satarupa Bhowmik how 80% of the bank's engineers use AI agents to triple code output and resolve over 15,000 security issues. | G4: [-0.012538, 0.012886, -0.11598, -0.005814, -0.089956, -0.032957, 0.043721, 0.082678, -0.035048, 0.01316, -0.038461, -0.068234, 0.036145, -0.036582, -0.028382, 0.116206, 0.019069, 0.014053, -0.070664, -0.1064, -0.031932, -0.077033, -0.036367, -0.034444, 0.003838, 0.030171, 0.040133, -0.088762, 0.010082, -0.058986, 0.006572, 0.054676, 0.100891, 0.004948, 0.009633, 0.012246, -0.018043, -0.011169, 0.093883, 0.019782, 0.010248, 0.002191, -0.024807, -0.092982, 0.066974, 0.027927, -0.021135, 0.063507, 0.021954, -0.008183, -0.060854, 0.036045, 0.011878, -0.00715, -0.042957, -0.060149, 0.049593, 0.001918, 0.088954, 0.022975, 0.034834, 0.034375, 0.053378, 0.066969, 0.183508, 0.005532, -0.085799, -0.076195, -0.058584, -0.018338, 0.040762, -0.048662, -0.040217, -0.060891, 0.07552, -0.00237, -0.012567, -0.017897, 0.053917, -0.061292, -0.004508, -0.08257, 0.004646, 0.047036, -0.010004, 0.030193, 0.02728, 0.003996, 0.041833, 0.048937, 0.090065, -0.035102, 0.042766, 0.003832, 0.035909, 0.048584, -0.076269, -0.028611, -0.015235, 0.008419, 0.080715, 0.001148, -0.000155, -0.03026, -0.075797, 0.016371, 0.143877, -0.008828, 0.0454, -0.038075, -0.012482, 0.020257, 0.027133, -0.034793, 0.024219, 0.002945, -0.010138, 0.109592, 0.01223, 0.022075, 0.074014, 0.00107, -0.027407, 0.020481, 0.0196, 0.020437, -0.070226, 0.0, -0.042624, 0.0452, 0.023326, -0.045375, 0.018921, -0.031081, -0.02153, -0.00581, -0.003386, 0.030854, -0.081154, 0.041718, -0.010982, 0.033067, 0.001511, -0.032408, -0.026142, 0.017773, -0.004157, 0.002231, 0.092136, -0.110355, 0.016975, 0.006774, 0.058758, 0.072965, 0.034642, -0.015586, 0.056088, 0.017174, -0.087615, 0.035706, -0.070798, -0.02006, -0.033862, -0.000653, 0.029476, -0.017115, -0.017309, 0.095296, -0.080477, 0.085855, 0.05475, -0.038629, -0.05171, 0.034664, -0.001804, -0.015514, -0.02503, -0.027074, -0.081002, 0.004528, -0.01965, -0.072604, 0.096105, -0.068194, 0.030492, 0.021384, 0.080379, 0.116826, -0.009728, 0.018497, -0.117222, 0.113315, -0.057496, 0.028934, -0.023902, 0.040191, 0.032796, -0.007122, -0.003107, 0.060485, 0.030315, 0.015759, -0.072871, -0.049024, 0.029475, -0.012195, 0.011905, 0.000665, -0.070253, 0.041145, 0.051313, -0.046775, 0.052161, -0.029634, -0.051861, -0.015458, -0.044089, 0.041592, -0.047138, -0.058207, 0.040225, 0.039614, -0.049135, -0.0, -0.1088, -0.02088, 0.002344, 0.001043, 0.037515, -0.017319, 0.000204, -0.007947, 0.018575, 0.037813, -0.055391, 0.002078, 0.030917, 0.055635, 0.054329, -0.040387, 0.005575, -0.054586, 0.026178, -0.032376, 0.041309, 0.039063, -0.00494, 0.04099, 0.019094, 0.033209, -0.103917, 0.026027, 0.052565, 0.017713, -0.0255, -0.06144, -0.063419, 0.073401, -0.056011, 0.033297, 0.041506, -0.034539, 0.02213, 0.080139, 0.013188, -0.027608, -0.115665, -0.04915, 0.030941, -0.001455, -0.00201, -0.020398, -0.025183, -0.045501, 0.018307, -0.008492, -0.013365, -0.023606, -0.103591, 0.054052, 0.04594, 0.017769, 0.018514, -0.043038, 0.021456, -0.02933, 0.035968, 0.030423, -0.08433, 0.035473, 0.053018, 0.050903, -0.063372, -0.039404, 0.051286, -0.099418, -0.011927, 0.052264, -0.070936, 0.04837, -0.053236, -0.062916, 0.047004, -0.029872, -0.078039, -0.030709, 0.026335, 0.027209, 0.065038, 0.086251, 0.044912, -0.057703, 0.0024, 0.07178, -0.060155, -0.009911, 0.026767, 0.004656, -0.10232, -0.0, -0.057239, -0.028972, 0.034136, 0.007394, 0.074098, -0.040717, -0.108153, -0.004753, -0.0204, -0.011062, 0.054615, -0.033423, -0.052624, 0.057077, 0.06337, 0.010182, -0.026861, 0.003649, 0.004236, -0.064013, 0.067049, 0.051329, -0.027514, -0.069233, 0.002067, -0.04136, -0.05192, 0.079587, -0.032464, 0.035908, -0.052478, 0.056316, -0.001441, -0.017247, 0.10305, -0.027211, -0.021575, 0.019025, -0.004455, -0.044715, -0.00861, -0.004309, 0.017782, -0.031841, 0.080898, -0.032403, -0.136556, -0.082605, 0.074137, -0.094088, 0.01561, -0.044086, 0.007668, 0.116952, 0.177159, -0.028598, -0.017508, -0.046684, -0.016376, 0.017031, -0.014366, -0.033761, -0.046361, -0.060704]
A5: 4 | B5: c23b800e-0d81-4f22-b84c-948dcb872f02 | C5: CBA.AX | D5: Asian Stocks Choppy as Investors Weigh Pause in Bond Selloff | E5: Asian equities fluctuated between gains and losses Thursday afternoon as investors weighed a pause in the global bond selloff, while the yen strengthened to nearly a four-week high against the dollar. | F5: Asian Stocks Choppy as Investors Weigh Pause in Bond Selloff - Asian equities fluctuated between gains and losses Thursday afternoon as investors weighed a pause in the global bond selloff, while the yen strengthened to nearly a four-week high against the dollar. | G5: [0.01166, -0.045078, 0.045879, 0.066219, -0.024982, -0.065276, 0.024268, 0.033273, -0.003228, -0.031656, 0.041612, 0.042376, -0.085986, -0.013278, 0.022194, -0.015344, -0.014185, 0.058692, -0.06073, -0.038472, -0.040678, -0.037289, 0.032682, 0.061973, 0.059942, 0.028826, -0.012083, 0.008807, 0.057151, -0.012636, -0.074995, 0.023487, 0.000374, 0.006776, -0.014882, 0.021985, -0.025838, 0.033625, 0.007844, -0.042056, 0.001968, 0.075948, 0.093572, -0.065885, 0.028537, -0.041628, 0.004171, -0.015631, 0.029607, -0.022143, -0.019503, 0.042335, -0.007857, -0.017647, -0.025504, 0.051457, 0.032655, 0.048858, -0.005133, 0.035595, -0.019947, 0.044812, 0.019297, -0.000278, 0.000988, 0.104439, 0.02356, 0.027931, 0.049329, 0.023005, 0.05449, 0.043029, -0.006387, -0.013097, -0.087729, -0.013848, 0.010651, -0.022438, 0.011174, -0.00271, -0.008383, -0.06722, 0.013826, -0.12394, 0.009291, 0.024355, 0.06053, -0.046977, -0.015593, 0.069678, 0.095373, 0.104904, 0.029348, 0.020234, -0.075201, 0.041495, 0.012571, -0.0286, -0.049781, 0.06418, 0.083693, 0.116603, -0.015073, 0.002576, -0.022808, -0.058453, 0.014261, -0.008747, -0.077801, 0.020998, -0.037108, 0.084524, -0.085124, -0.024337, -0.074404, 0.04995, -0.0017, -0.001924, -0.063186, 0.056525, 0.018742, -0.020778, -0.114183, -0.037478, 0.033675, 0.033634, -0.033676, 0.0, 0.004758, -0.054605, 0.028967, 0.041596, -0.117996, -0.018905, -0.057436, -0.020961, -0.098505, -0.023601, -0.018707, -0.037743, -0.011243, -0.041731, 0.069663, -0.092043, -0.010237, 0.068788, 0.048288, 0.029477, 0.045045, -0.024801, -0.002657, -0.032868, -0.064297, -0.017185, -0.025025, 0.001052, -0.047524, 0.052729, -0.007851, -0.020372, -0.013719, 0.004016, -0.08452, -0.055563, -0.026181, 0.005199, 0.045685, -0.002484, 0.000282, 0.03763, -0.063839, -0.033618, 0.033652, -0.013905, 0.01948, -0.049662, -0.035418, 0.082995, -0.01328, 0.027864, 0.002958, 0.095382, 0.016237, -0.012581, 0.116385, -0.068982, -0.110692, 0.033835, -0.023058, 0.027063, -0.097349, -0.037314, -0.105712, 0.082054, -0.024521, -0.030074, -0.168051, 0.042726, -0.002079, -0.040548, 0.054226, 0.040307, 0.011747, -0.059792, -0.056728, -0.02453, 0.029193, 0.034229, 0.065958, 0.005387, 0.041434, -0.007925, -0.06645, 0.026314, 4.5e-05, -0.011586, 0.051071, -0.008738, -0.018531, 0.002334, 0.096344, -0.014415, 0.009125, -0.0, -0.038556, -0.007143, -0.116241, 0.02376, 0.001491, 0.019246, 0.018153, 0.072684, -0.053585, -0.077295, 0.023441, -0.062653, -0.047262, 0.092164, -0.025025, -0.062096, 0.158013, 0.082233, 0.079285, -0.020674, 0.069573, -0.057856, 0.046898, 0.045126, 0.037668, 0.040798, -0.019251, 0.078258, 0.005124, 0.012284, 0.003385, 0.033115, 0.029506, 0.052861, -0.014158, 0.0048, -0.073127, -0.019282, -0.057968, -0.022594, -0.04742, 0.017942, 0.069864, 0.05258, 0.035696, 0.040778, 0.011961, 0.035558, -0.019948, -0.025275, -0.002721, 0.034306, -0.009934, 0.025149, -0.061497, 0.03215, -0.036708, -0.06489, -0.057958, 0.022006, -0.05226, -0.012589, 0.006918, 0.034028, 0.010144, -0.07104, 0.111345, -0.043653, 0.071207, -0.070872, 0.037237, -0.030551, 0.013688, -0.019339, 0.003105, 0.096441, -0.05834, -0.018672, 0.040315, 0.023548, 0.01855, 0.060555, 0.020461, 0.038869, -0.08989, 0.094791, -0.127003, 0.011066, 0.036082, 0.006766, -0.000175, 0.023678, 0.041795, -0.010548, 0.005947, -0.0, -0.004423, -0.096633, -0.018244, 0.032127, -0.084626, 0.016056, 0.054336, 0.02427, 0.073423, 0.005567, 0.033525, -0.010986, -0.056814, 0.009017, -0.104203, -0.078396, -0.037538, 0.126278, -0.020021, -0.047642, 0.062633, -0.053607, 0.060259, -0.04331, 0.006032, 0.03836, -0.071088, 0.07423, -0.016048, -0.036511, 9.2e-05, -0.073981, 0.080829, 0.080968, 0.062867, 0.0646, 0.019051, 0.014208, 0.003943, 0.045758, -0.023997, -0.068819, 0.009008, 0.023744, 0.067881, -0.021952, -0.004589, 0.060232, 0.123246, -0.09046, -0.023378, -0.039937, -0.088857, 0.000914, 0.003661, 0.004484, -0.008284, 0.021053, -0.042193, 0.008918, -0.055059, -0.106722, -0.150966, 0.093932]
A6: 5 | B6: 6192bccf-9d89-4bdf-b571-47e3e02b311d | C6: CBA.AX | D6: 3 Australian Dividend Stocks With At Least 3% Yield | E6: With Australian credit growth still resilient, income investors are looking harder at local businesses that share profits through dividends. Higher global interest rate expectations have pushed up funding costs, so reliable cash payouts from established Australian dividend stocks can feel even more valuable. This article walks through three higher yielding dividend options from a focused screener and explains why they may deserve a closer look now. The three stocks in this article are just a... | F6: 3 Australian Dividend Stocks With At Least 3% Yield - With Australian credit growth still resilient, income investors are looking harder at local businesses that share profits through dividends. Higher global interest rate expectations have pushed up funding costs, so reliable cash payouts from established Australian dividend stocks can feel even more valuable. This article walks through three higher yielding dividend options from a focused screener and explains why they may deserve a closer look now. The three stocks in this article are just a... | G6: [-0.033398, -0.06279, -0.035794, 0.019417, 0.038975, 0.048319, -0.003688, -0.022353, 0.063222, 0.038204, 0.012999, 0.001172, -0.097216, 0.075997, -0.0003, -0.00179, -0.054892, -0.022133, 0.00314, 0.017766, -0.088347, -0.025548, 0.00551, 0.024832, 0.140462, 0.006124, -0.03393, 0.028531, 0.035762, -0.032797, 0.029336, 0.137494, 0.123737, -0.067748, -0.023733, 0.012263, -0.004666, 0.004278, 0.038314, 0.0256, 0.025714, 0.036501, 0.047901, -0.04613, -0.05459, -0.096765, 0.042904, -0.073374, 0.033903, 0.040374, -0.018402, 0.019302, 0.002976, -0.09142, -0.028839, -0.08282, -0.025024, 0.02538, 0.02701, -0.023369, 0.01654, 0.007606, 0.05696, -0.018498, 0.059522, 0.038679, -0.057804, 0.064672, -0.06199, -0.011219, -0.022834, -0.010549, -0.073946, -0.087633, -0.087294, 0.031744, 0.059974, 0.026554, -0.015915, -0.019208, -0.045571, -0.024149, 0.005349, 0.033407, -0.052269, -0.079067, 0.074379, -0.032687, 0.045162, -0.014693, -0.011429, 0.035333, 0.033186, 0.020033, 0.014854, 0.01113, -0.091109, -0.101596, -0.120284, -0.035603, 0.10646, 0.094692, -0.00985, 0.025594, 0.027317, -0.015588, -0.044961, -0.008552, 0.096738, 0.037279, 0.011717, 0.087717, -0.042879, -0.036077, -0.078595, 0.005879, -0.085958, -0.005871, 0.088067, 0.042463, 0.065902, 0.053821, -0.038762, -0.073755, 0.086091, -0.003615, -0.034206, 0.0, 0.009703, 0.021216, 0.070019, 0.073728, 0.052045, -0.054178, -0.027717, -0.047258, -0.083541, 0.007728, -0.011361, 0.035057, 0.064703, -0.028337, 0.017274, -0.044751, -0.039663, 0.031756, 0.040799, 0.087544, 0.053848, 0.01641, 0.044853, -0.050545, 0.090704, -0.074787, 0.018263, 0.018384, -0.002795, 0.004046, 0.02732, 0.038173, -0.077415, -0.048141, -0.06172, 0.004771, -0.017529, 0.000809, 0.017799, -0.016633, -0.002985, -0.028749, -0.022404, 0.024168, 0.028551, -0.005224, -0.009965, -0.034465, 0.004665, 0.078241, -0.039024, 0.014724, -0.034574, 0.006383, -0.019045, -0.028243, -0.064125, -0.000688, -0.010846, -0.041689, 0.023454, -0.019199, -0.107235, -0.026625, -0.094381, 0.098856, 0.035136, -0.026396, -0.068526, 0.107121, -0.052185, 0.011528, 0.076394, -0.01146, -0.026023, -0.025964, -0.072124, 0.031739, 0.093549, -0.00537, 0.021419, 0.016444, -0.012508, -0.029643, -0.011814, 0.016027, 0.023039, -0.020618, 0.050984, -0.010706, -0.044593, -0.039208, 0.059729, -0.074656, -0.011816, -0.0, -0.008591, -0.075617, -0.006539, -0.013521, -0.030857, -0.025071, 0.038225, 0.007591, 0.016773, 0.014862, -0.040274, 0.107347, 0.016274, 0.002994, -0.017096, -0.020261, 0.081323, -0.034544, 0.092009, -0.116082, 0.055895, -0.018632, -0.053243, 0.071107, 0.014677, 0.071351, -0.091858, -0.024914, 0.024415, -0.049953, -0.071365, 0.04838, -0.041459, 0.025277, -0.030129, 0.01361, -0.047325, 0.023822, -0.002481, 0.08349, -0.017651, -0.002211, 0.012861, 0.004057, -0.035281, 0.008211, 0.008024, 0.060645, 0.023984, 0.027451, -0.031405, 0.012911, -0.054424, 0.088261, -0.033515, 0.044367, -0.054878, 0.006243, 0.012216, 0.054401, -0.021411, 0.126845, -0.001505, 0.012, -0.002952, 0.020292, -0.058679, 0.051607, -0.010668, -0.028921, 0.073891, -0.050505, 0.104447, -0.037335, 0.064165, 0.154246, -0.011543, -0.036576, -0.016681, 0.032215, 0.071552, 0.002008, 0.013224, 0.122084, -0.084288, 0.050927, 0.038767, -0.005652, 0.048191, -0.089701, -0.073369, -0.060396, 0.061385, 0.096097, 0.01883, -0.0, -0.059885, -0.063388, -0.071662, -0.021733, -0.010966, 0.001806, 0.035117, 0.023631, 0.036891, 0.004711, 0.041199, -0.029597, -0.086464, 0.001602, -0.020442, -0.015193, -0.037965, 0.018388, -0.014379, -0.049863, 0.026017, 0.011295, 0.058429, 0.005308, -0.019795, 0.062008, -0.021962, -0.012166, -0.056835, 0.080527, -0.010668, 0.023586, 0.023859, 0.03552, -0.023938, 0.002734, 0.020568, 0.033199, 0.042637, 0.037863, -0.033515, -0.120465, -0.082945, -0.015058, -0.096109, -0.015225, -0.085004, 0.000666, -0.013544, -0.128217, -0.023672, 0.009895, -0.034127, 0.099384, 0.018129, 0.001479, -0.104063, -0.006772, 0.014251, -0.028147, -0.038325, -0.161041, 0.028854, 0.077417]
A7: 6 | B7: c385b2b8-f8e0-4278-99be-f30dbd1d2167 | C7: CBA.AX | D7: 3 Australian Dividend Stocks Paying Over 5% While Cash Income Looks Less Certain | E7: With bond yields across major markets reflecting expectations for tighter central bank policy, income from cash and short-term bonds can feel uncertain again. Reliable dividend income looks more valuable when policy paths shift and inflation stays in focus. Dividend powerhouses with yields above 5% and well covered, growing payouts offer one way to seek steadier cash flow. This article highlights three stocks from that screener. The three dividend stocks covered next are just a sample from... | F7: 3 Australian Dividend Stocks Paying Over 5% While Cash Income Looks Less Certain - With bond yields across major markets reflecting expectations for tighter central bank policy, income from cash and short-term bonds can feel uncertain again. Reliable dividend income looks more valuable when policy paths shift and inflation stays in focus. Dividend powerhouses with yields above 5% and well covered, growing payouts offer one way to seek steadier cash flow. This article highlights three stocks from that screener. The three dividend stocks covered next are just a sample from... | G7: [-0.057789, -0.067497, -0.038848, -0.006074, 0.049677, 0.020223, 0.014186, -0.059408, 0.01436, 0.042265, -0.005234, -0.016453, -0.106396, 0.047942, 0.016012, -0.00426, -0.026763, 0.017775, 0.000381, 0.013634, -0.046898, -0.043421, 0.004105, 0.025199, 0.139629, 0.040418, -0.023361, -0.002571, 0.020517, -0.042867, 0.061013, 0.080699, 0.072357, -0.039605, -0.045642, 0.010168, 0.009997, -4.8e-05, 0.047278, 0.082704, 0.016979, 0.008351, 0.038544, -0.049847, -0.044101, -0.103143, 0.02416, -0.031182, 0.030648, 0.026158, -0.012523, -0.001473, -0.000913, 0.005809, -0.043978, -0.052525, -0.006718, -0.000299, 0.008393, -0.020836, 0.012688, -0.002832, 0.051301, -0.011281, 0.023451, 0.021341, -0.061939, 0.061655, -0.067781, -0.026301, -0.046574, -0.027186, -0.062216, -0.095079, -0.103491, 0.015898, 0.085154, 0.02442, -0.014672, -0.051802, -0.022162, 0.021543, 0.003211, 0.006509, -0.035044, -0.085559, 0.048169, -0.034129, 0.019443, -0.025696, 0.002839, 0.02999, 0.019448, 0.03569, 0.035328, 0.023285, -0.068716, -0.07827, -0.06906, -0.02592, 0.122069, 0.107166, 0.013062, 0.062032, 0.045799, -0.01173, -0.050353, -0.006879, 0.049229, -0.003461, 0.019959, 0.083248, -0.003547, -0.024443, -0.043091, 0.003731, -0.085223, 0.020454, 0.096838, 0.064675, 0.087864, 0.058495, 0.004078, -0.06512, 0.102333, 0.024386, 0.017787, 0.0, 0.001994, -5.1e-05, 0.065808, 0.107051, 0.036778, -0.042468, -0.025758, -0.058192, 0.001896, -0.001499, -0.023045, 0.034614, 0.035516, 0.006262, -0.015021, -0.051388, -0.075963, 0.054759, 0.043029, 0.093616, 0.009189, 0.007084, 0.017914, -0.034358, 0.096235, -0.034361, 0.012088, -0.0101, -0.00195, 0.033213, 0.027337, 0.07503, -0.049076, -0.087093, -0.077342, -0.006631, 0.002283, 0.001169, 0.027754, -0.03903, -0.010375, -0.06847, 0.005258, 0.003921, -0.04097, -0.043363, -0.024966, -0.007764, 0.007943, 0.035952, -0.015335, -0.01482, -0.018724, -0.008239, -0.037553, -0.040308, -0.062483, -0.020336, -0.023894, -0.029331, -0.021219, 0.001352, -0.127114, -0.008723, -0.112472, 0.111268, 0.032436, 0.015765, -0.060501, 0.119657, -0.034973, 0.02492, 0.059728, 0.046371, -0.012712, 0.007579, -0.047222, 0.04256, 0.039228, -0.010427, 0.004235, 0.024952, 0.035992, -0.035569, 0.003434, 0.037745, 0.026836, -0.043642, 0.074315, -0.026255, -0.031465, -0.064899, 0.08472, -0.062155, -0.03526, -0.0, -0.002052, -0.006679, -0.027615, -0.013196, -0.065484, 0.000394, 0.053862, 0.006183, 0.004691, 0.056055, -0.045581, 0.112403, -0.025977, -0.024802, -0.002404, -0.01926, 0.064333, -0.060075, 0.07225, -0.094624, 0.084337, -0.041552, -0.061363, 0.103425, 0.03307, 0.078318, -0.131589, -0.039977, 0.031958, 0.000666, -0.012725, -0.031753, -0.016135, -0.025302, -0.020049, 0.012433, -0.063916, 0.024233, -0.029964, 0.079661, -0.043997, -0.018943, 0.042876, 0.006462, -0.027361, -0.027067, -0.00616, 0.057294, 0.041192, 0.033815, -0.020099, 0.036538, -0.03292, 0.099595, -0.06194, 0.062362, -0.053626, 0.034991, -0.036331, 0.0341, -0.033094, 0.092096, -0.003643, -0.025441, 0.017592, 0.01472, -0.079181, 0.040033, -0.000554, -0.014478, 0.067502, -0.038933, 0.132521, -0.040808, 0.08462, 0.1724, -0.005219, -0.034553, -0.015078, 0.105288, 0.032454, -0.029884, 0.040922, 0.077575, -0.12378, 0.069438, 0.029925, -0.028446, 0.059766, -0.088874, -0.044461, -0.077104, 0.016394, 0.056768, 0.033577, -0.0, -0.025527, -0.070194, -0.034646, -0.057568, -0.028021, -0.0212, 0.019247, -0.007769, 0.055982, -0.003377, 0.032101, 0.012563, -0.04556, -0.024229, -0.045145, -0.016047, -0.052995, 0.015026, -0.016144, -0.081697, 0.041519, 0.008948, 0.023312, 0.01031, -0.016526, 0.06601, 0.005115, 0.008435, -0.050238, 0.069294, 0.00343, 0.020149, 0.022777, -0.003936, 0.022554, 0.047384, 0.089271, 0.006344, 0.047465, 0.081789, -0.019996, -0.144097, -0.056617, -0.010449, -0.081477, -0.013347, -0.097098, 0.010297, -0.025274, -0.161412, -0.018316, 0.027139, -0.060505, 0.084407, 0.005605, -0.056244, -0.104534, 0.011109, 0.008219, -0.039767, -0.035579, -0.108341, 0.058339, 0.08328]
A8: 7 | B8: 3197f837-7d31-4fd0-9208-cca4c823c4f2 | C8: CBA.AX | D8: Three of Australia's four major banks forecast another rate hike this year | E8: SYDNEY, Aug 27 (Reuters) - The Commonwealth Bank of Australia and the National Australia Bank on Thursday joined ANZ in forecasting another rate hike this year after a hot inflation print reignited | F8: Three of Australia's four major banks forecast another rate hike this year - SYDNEY, Aug 27 (Reuters) - The Commonwealth Bank of Australia and the National Australia Bank on Thursday joined ANZ in forecasting another rate hike this year after a hot inflation print reignited | G8: [-0.012481, -0.089297, -0.074646, 0.090728, 0.00413, 0.011362, -0.042485, -0.020466, -0.013267, 0.053397, -0.024232, -0.035385, -0.034141, 0.067862, 0.022673, 0.031259, -0.147181, -0.022818, -0.004399, -0.05586, -0.034669, -0.052577, -0.022253, -0.003983, 0.061569, -0.017235, -0.029606, 0.030687, -0.050763, -0.023831, -0.066742, 0.088887, -0.041855, -0.078016, 0.050129, -0.058526, -0.003425, 0.022525, -0.005074, 0.003898, 0.101183, 0.036508, 0.042075, 0.006503, -0.015163, 0.00705, -0.005446, -0.002163, -0.030186, 0.096998, -0.018457, -0.036562, 0.020815, -0.044477, -0.025067, -0.019503, -0.028591, -0.033877, 0.015728, -0.096853, 0.008592, 0.009368, -0.027925, -0.006067, 0.059894, 0.072825, -0.103585, -0.007393, -0.061148, -0.002908, -0.085563, -0.139079, 0.021162, -0.104836, -0.007875, -0.041084, 0.153892, 0.049792, 0.00806, -0.047913, 0.03201, -0.079706, 0.015977, -0.049254, -0.008581, -0.057645, 0.06157, -0.038224, 0.013095, 0.015502, 0.014669, 0.058092, 0.043053, -0.003379, -0.004651, 0.018286, -0.071806, -0.057019, 0.051024, 0.002236, 0.134502, 0.068002, 0.051792, 0.140443, 0.052116, 0.043389, -0.051361, -0.006195, 0.053082, 0.012356, 0.011348, 0.093648, 0.016355, -0.054329, -0.023662, 0.054115, -0.012997, 0.073378, 0.035261, 0.083444, -0.004557, -0.01556, 0.049098, -0.047411, 0.105864, 0.059153, -0.082906, -0.0, -0.04459, 0.030545, 0.05208, -0.05746, 0.043108, -0.038346, -0.040713, 0.010267, -0.032947, -0.036429, -0.013168, 0.043416, 0.065329, 0.042315, -0.066803, -0.069326, 0.070583, 0.006289, 0.01961, 0.11586, -0.026012, 0.036539, -0.005753, 0.007076, -0.000273, -0.001441, 0.097347, 0.010847, -0.011151, -0.006439, 0.022654, 0.013291, -0.075208, -0.058027, 0.016691, -0.022115, 0.059968, 0.021055, 0.018801, -0.03295, 0.032079, -0.032073, 0.002828, -6.2e-05, -0.013797, 0.056735, -0.098866, -0.07747, -0.02468, -0.006015, -0.017341, -0.045379, -0.087895, 0.010185, 0.012933, -0.026293, -0.107196, -0.005251, 0.090934, -0.009861, -0.001225, -0.058138, -0.102678, -0.018638, -0.039532, 0.00866, 0.069443, 0.000832, -0.069702, 0.061821, -0.046568, 0.008132, 0.044403, 0.045084, -0.001183, 0.028219, 0.04048, -0.024395, 0.063584, -0.010956, -0.059086, 0.062314, 0.030957, -0.01316, 0.002154, -0.050211, 0.003763, -0.017579, 0.046342, -0.054251, -0.030817, -0.011359, 0.035577, 0.007409, 0.027087, -0.0, 0.038513, 0.024147, -0.021706, 0.018278, -0.03554, -0.084068, 0.096959, 0.004761, 0.044852, -0.015903, 0.022014, 0.107664, 0.017528, -0.026077, 0.067362, 0.019373, 0.072588, -0.046754, 0.051634, -0.045009, 0.002816, -0.06276, -0.013236, 0.068527, -0.129242, 0.031451, -0.01048, -0.025802, -0.07249, -0.00722, -0.100037, -0.005887, 0.047256, -0.021109, -0.079489, 0.054966, 0.000234, -0.012772, -0.039824, 0.056163, 0.005542, 0.069543, -0.022919, -0.048356, -0.010459, 0.065063, -0.012007, 0.079553, -0.030604, 0.055914, -0.014365, -0.005876, -0.045089, 0.004353, -0.055726, 0.022117, 0.042125, -0.047094, -0.022967, 0.059381, 0.052688, 0.070566, 0.040667, -0.019341, 0.052504, -0.044582, 0.020528, -0.049456, 0.037093, -0.009087, -0.005951, 0.051257, -0.044309, 0.062299, 0.044287, 0.074119, -0.022479, -0.063714, 0.008179, 0.015093, -0.056673, 0.04738, 0.020745, 0.090178, -0.068882, -0.030768, 0.111254, -0.01577, 0.07085, -0.121569, -0.01956, -0.043861, 0.009467, 0.075426, -0.060046, -0.0, -0.040154, -0.069876, -0.005774, -0.003656, 0.015957, -0.003267, 0.00301, 0.074665, 0.08221, -0.00425, 0.09848, 0.020706, -0.043107, 0.011746, 0.045996, 0.05163, -0.009444, -0.036418, -0.022765, -0.092553, -0.055722, 0.08874, -0.012259, -0.013041, 0.034269, 0.014451, -0.013898, 0.084348, 0.008778, -0.010286, -0.049741, 0.023665, 0.026901, -0.048588, -0.023587, -0.023528, 0.098475, 0.014039, 0.065901, -0.018287, 0.013341, -0.085884, -0.055978, 0.00102, -0.048944, -0.056165, -0.058136, -0.058296, -0.009957, -0.061462, -0.029323, 0.043408, -0.015728, 0.080987, 0.029282, -0.106129, -0.103175, -0.047454, -0.000995, -0.014196, 0.050634, -0.123114, -0.031532, -0.009935]
A9: 8 | B9: 8c255177-b931-4783-a1bf-9e2dacfa1b3c | C9: CBA.AX | D9: Commonwealth Bank Stock And 2 More Dividend Shares For Reliable Income | E9: Rising yields in major markets are pushing income investors to think harder about where their cash flow comes from. With bond markets adjusting to tighter policy signals, dependable company dividends can feel more valuable than ever. That is where the Dividend Powerhouses 3%+ Yield screener comes in. This article walks through three high income stocks on that list and what makes their dividend profiles worth a closer look. The three stocks below are just a starting sample, and the full... | F9: Commonwealth Bank Stock And 2 More Dividend Shares For Reliable Income - Rising yields in major markets are pushing income investors to think harder about where their cash flow comes from. With bond markets adjusting to tighter policy signals, dependable company dividends can feel more valuable than ever. That is where the Dividend Powerhouses 3%+ Yield screener comes in. This article walks through three high income stocks on that list and what makes their dividend profiles worth a closer look. The three stocks below are just a starting sample, and the full... | G9: [-0.004529, -0.088327, -0.03772, 0.019162, 0.018223, 0.01208, 0.014884, -0.024524, 0.014824, -0.000428, -0.018432, 0.018914, -0.0798, 0.055464, 0.040882, -0.006228, -0.002003, 0.042121, 0.003666, 0.009708, -0.047172, -0.076137, 0.036173, 0.005862, 0.096305, -0.001359, -0.023781, 0.00557, -0.001382, -0.0691, 0.002063, 0.07754, 0.080843, -0.033729, 0.007586, -0.017102, 0.042711, 0.0592, 0.06813, 0.016906, 0.025465, 0.007664, 0.04784, 0.030521, 0.007643, -0.063344, 0.039899, -0.027337, 0.040985, 0.014297, -0.050866, 0.00537, 0.041791, -0.052264, -0.029743, -0.038775, -0.063049, 0.045826, 0.093519, -0.036714, -0.003311, 0.030946, 0.058381, -0.0033, 0.085644, 0.009215, -0.025081, 0.091884, -0.051982, -0.025431, -0.028614, -0.035247, -0.081366, -0.111993, -0.104262, 0.025818, 0.045064, 0.025598, -0.02613, -0.022196, -0.018517, 0.006548, 0.021709, 0.012863, -0.004606, -0.068554, 0.046796, -0.028772, -0.001632, -0.019072, -0.014589, 0.00245, 0.061374, 0.005108, 0.028322, 0.040976, -0.074128, -0.104445, -0.074403, 0.000517, 0.092284, 0.119734, -0.005679, 0.10129, 0.046889, -0.020167, -0.064529, 0.010292, 0.08174, 0.037341, 0.051029, 0.113491, -0.058085, -0.041687, -0.053233, -0.024125, -0.029333, 0.018046, 0.100735, 0.080306, 0.091249, -0.010274, -0.028385, -0.046852, 0.084757, 0.008887, -0.041933, 0.0, -0.012168, 0.035764, 0.065847, 0.085491, 0.00582, -0.020191, -0.041646, -0.038427, -0.076389, 0.005141, -0.05672, 0.053396, 0.053577, 0.009853, 0.00458, -0.030604, -0.038561, 0.056082, 0.044244, 0.042178, -0.027739, 0.027874, 0.027928, -0.04493, 0.080676, -0.094956, -0.010328, 0.005525, 0.023172, 0.036468, 0.050089, 0.012159, -0.054213, -0.037938, -0.071686, -0.012377, -0.048514, -0.015765, 0.048301, -0.034355, -0.021512, -0.052949, 0.036801, 0.0266, -0.038888, -0.009613, -0.025262, -0.0225, -0.014878, 0.035473, -0.021639, -0.006, -0.091515, -0.019695, -0.040213, -0.025322, -0.03439, -0.011092, -0.002817, -0.00183, -0.017928, -0.003483, -0.137087, -0.000604, -0.071849, 0.085072, -0.016167, 0.045813, -0.078667, 0.127031, -0.017927, 0.026309, 0.043924, -0.012915, -0.021677, 0.026149, -0.03615, 0.028537, 0.070771, -0.003309, 0.039857, 0.001859, 0.023904, -0.008027, -0.014211, 0.015628, -0.021452, -0.011928, 0.053143, -0.010207, -0.015406, -0.073737, 0.092637, -0.040573, -0.032598, -0.0, -0.026613, -0.012378, 0.006217, -0.047479, -0.074155, -0.068773, 0.063253, -0.059191, -0.021617, 0.042865, -0.003411, 0.028059, 0.011261, 0.063988, -0.066075, -0.020844, 0.04816, -0.042628, 0.1088, -0.073522, 0.069332, -0.014595, -0.018991, 0.098499, -0.037155, 0.079467, -0.14488, -0.034714, 0.051874, 0.005879, -0.056719, -0.014562, -0.024233, -0.028371, -0.037775, 0.027835, -0.071294, -0.03415, 0.016213, 0.093502, -0.007764, 0.001179, -0.00864, -0.05295, 0.031381, 0.046958, 0.07113, 0.056544, 0.079115, 0.007428, -0.01303, 0.04492, -0.037546, 0.136016, -0.043332, 0.030177, -0.044606, 0.016257, -0.007054, 0.012323, -0.028253, 0.084676, -0.00858, -0.009576, 0.019923, 0.027827, -0.0851, 0.051541, 0.000928, -0.040617, 0.054757, -0.067783, 0.135692, -0.037695, 0.014172, 0.12176, -0.005345, -0.074949, 0.002311, 0.068505, 0.042108, 0.011378, 0.001376, 0.084193, -0.092431, 0.051161, 0.045452, -0.039669, 0.04115, -0.085509, -0.047999, -0.032542, 0.060841, 0.10181, 0.020558, -0.0, -0.021126, -0.07759, -0.053878, -0.059245, 0.036207, -0.082662, 0.019591, 0.005212, 0.040888, 0.003107, 0.010643, -0.013468, -0.075324, -0.059212, 0.022025, 0.027008, -0.033228, -0.033216, 0.005207, -0.095689, 0.064721, -0.003049, 0.083104, 0.000514, -0.070823, 0.044436, 0.022357, -0.025397, -0.010078, 0.048202, -0.017247, 0.005113, 0.016081, 0.00803, 0.012433, 0.037507, 0.024692, -0.024871, 0.087465, 0.072746, -0.033831, -0.113158, -0.069675, 0.045738, -0.014795, -0.041902, -0.053653, 0.017604, -0.034, -0.186873, -0.042654, 0.014995, -0.039922, 0.100883, 0.014552, -0.025616, -0.121687, 0.010744, -0.007823, -0.025065, -0.020446, -0.092016, 0.051763, 0.042317]
A10: 9 | B10: 413c847a-f31f-48e9-8aa3-215b13213f26 | C10: CBA.AX | D10: Commonwealth Bank unveils payout platform ahead of cheque exit | E10: PaidIt combines recipient verification, communications and payment delivery within one system. | F10: Commonwealth Bank unveils payout platform ahead of cheque exit - PaidIt combines recipient verification, communications and payment delivery within one system. | G10: [0.003039, 0.048538, -0.059951, -0.032072, 0.021904, 0.00507, 0.077272, -0.042013, 0.00436, 0.018521, 0.008259, -0.035445, -0.020477, -0.030273, 0.050149, -0.056632, -0.012615, 0.002583, 0.02737, 0.01361, -0.069013, -0.061577, -0.026105, 0.007186, 0.017522, -0.046949, -0.035053, 0.009776, -0.064786, -0.037038, 0.009514, 0.037567, -0.050402, -0.013724, -0.002315, 0.041878, -0.005673, 0.005766, -0.137871, -0.09111, 0.019019, -0.04543, -0.047175, 0.028821, 0.067832, 0.060526, -0.027839, 0.049259, -0.070811, 0.004708, 0.062417, -0.043993, 0.033604, 0.10229, -0.074849, 0.019303, 0.058452, 0.013633, -0.00793, -0.117637, -0.006319, 0.021799, -0.095868, 0.019443, 0.050439, 0.060723, -0.019642, 0.028235, -0.002422, -0.064052, -0.03663, -0.087194, 0.035479, -0.01948, 0.004408, 0.097474, 0.063014, -0.009476, -0.005301, 0.033495, 0.032608, 0.078002, -0.047615, 0.004736, 0.031484, -0.007102, -0.025048, 0.011717, 0.018453, -0.104228, -0.042005, 0.043246, 0.106976, -0.068994, 0.058966, -0.083061, 0.013162, -0.043273, 0.066555, -0.005726, 0.10384, 0.061884, 0.029854, -0.001092, 0.073161, 0.069053, 0.003892, 0.015145, 0.153194, -0.047851, -0.024987, -0.02687, 0.076382, 0.002874, 0.061226, 0.120404, -0.094396, 0.087347, 0.097589, -0.025455, 0.021076, -0.001035, -0.073686, -0.124663, 0.005216, 0.012246, 0.027541, 0.0, -0.062279, -0.033208, 0.067412, 0.043127, 0.088416, -0.044801, -0.05452, 0.008989, -0.043747, 0.034044, -0.023896, -0.028276, 0.032761, 0.086224, -0.018633, -0.020775, 0.016351, 0.066151, 0.099192, 0.107618, -0.01892, -0.025774, 0.013264, -0.019929, 0.060981, 0.030106, -0.041889, -0.015041, 0.020449, -0.013093, -0.001393, -0.008656, -0.050846, 0.058432, -0.101906, -0.005682, -0.000671, -0.076294, 0.081126, -0.080318, -0.021546, -0.057455, 0.002535, 0.023516, -0.047986, -0.009434, -0.005089, -0.062365, 0.093436, 0.025644, -0.005862, 0.013876, -0.084318, -0.028866, 0.001621, -0.035558, 0.050704, 0.043371, -0.005599, -0.047496, -0.028172, -0.002565, -0.07198, -0.054288, 0.004234, 0.026336, -0.061189, -0.052616, -0.016315, 0.036913, -0.062812, 0.107168, 0.070581, 0.014653, -0.015231, 0.016041, -0.016679, -0.002245, 0.104737, 0.099705, 0.036349, 0.046712, -0.05835, 0.005888, 0.066205, -0.002324, 0.006801, -0.095952, -0.000874, -0.043414, 0.000633, -0.006933, -0.010451, 0.083232, 0.087538, -0.0, -0.037081, -0.029996, -0.036283, 0.076076, -0.069415, -0.002282, 0.005954, -0.036479, 0.092258, 0.071094, -0.041877, 0.002949, 0.082882, -0.015515, 0.035248, -0.045813, -0.010137, -0.05177, 0.059639, 0.041263, 0.087236, 0.002428, 0.015877, -0.016855, 0.064924, 0.010171, 0.009083, -0.106705, -0.017107, -0.005261, 0.036537, -0.022528, -0.015218, -0.046678, -0.029242, -0.04883, -0.057106, 0.065078, 0.021956, 0.073488, -0.029865, -0.049438, -0.061491, 0.021561, 0.006026, -0.059757, -0.048315, 0.082295, 0.081569, 0.017819, 0.017452, 0.012208, -0.009909, 0.08011, -0.015169, 0.107127, 0.060818, 0.043415, -0.026563, -0.015185, 0.012639, -0.045839, 0.021721, -0.040536, 0.071637, 0.034938, -0.01697, 0.043934, 0.020407, -0.019311, -0.016912, -0.032586, 0.042016, -0.038809, 0.055019, 0.078575, -0.024702, -0.096722, -0.037866, 0.043778, -0.043553, -0.027449, 0.078503, 0.080323, 0.016865, -0.070829, -0.010886, -0.084274, -0.015931, -0.047004, -0.00235, -0.03892, 0.093375, 0.041956, -0.054079, -0.0, -0.009334, -0.024866, -0.036326, -0.041113, -0.010535, -0.045983, -0.003618, 0.055123, -0.048328, -0.026099, -0.028609, -0.024708, -0.013939, 0.006138, 0.027946, 0.049712, 0.047511, -0.069521, -0.058612, -0.000283, 0.006237, -0.017897, -0.060841, -0.035299, -0.112494, -0.01085, 0.059426, 0.069992, 0.013956, -0.072045, -0.079755, 0.008839, -0.022407, 0.00433, 0.084573, 0.075236, 0.073775, 0.0134, 0.002321, 0.01507, -0.019966, -0.042246, -0.091533, 0.006507, -0.03262, 0.001351, -0.057575, 0.058363, -0.075239, -0.061165, 0.021292, -0.018057, 0.007693, 0.046459, 0.039756, -0.038405, -0.021203, 0.003197, 0.108863, 0.08815, -0.009258, -0.032166, 0.071891, -0.088588]
A11: 10 | B11: 686cdb0c-4e0e-4c16-82e8-cc5fb13cd2ca | C11: CBA.AX | D11: Australian bank investors brace for tough times as mortgage demand plummets | E11: By Christine Chen and Scott Murdoch SYDNEY, Aug 25 (Reuters) - Investors are questioning the rich valuations on Australia's biggest banks as a downturn in lucrative mortgage lending threatens to | F11: Australian bank investors brace for tough times as mortgage demand plummets - By Christine Chen and Scott Murdoch SYDNEY, Aug 25 (Reuters) - Investors are questioning the rich valuations on Australia's biggest banks as a downturn in lucrative mortgage lending threatens to | G11: [0.052726, -0.081897, -0.036968, 0.029312, -0.085031, -0.002879, -0.035874, 0.044571, -0.042926, 0.025475, -0.062607, 0.010172, -0.0446, 0.025229, 0.034985, 0.008114, -0.037028, -0.030835, 0.005956, 0.072647, -0.062635, -0.038834, -0.059913, -0.012119, 0.075357, 0.000967, 0.036313, 0.029956, 0.020128, -0.003434, -0.04865, 0.045097, -0.006596, -0.017475, 0.064961, 0.025881, -0.008346, -0.031173, 0.009937, -0.049398, 0.080566, -0.027419, 0.023986, -0.036022, -0.054992, -0.035897, 0.107157, 0.045079, -0.01668, 0.066605, -0.065557, 0.004005, 0.068107, -0.096222, -0.023443, 0.027864, 0.027886, 0.000599, 0.023047, -0.045323, 0.069265, 0.034469, 0.033502, 0.011377, 0.084644, 0.06631, -0.052825, 0.010431, -0.044406, 0.029597, -0.005163, -0.137047, -0.02021, -0.086881, 0.000494, -0.024045, 0.067445, -0.017881, 0.020899, -0.047949, 0.106549, -0.160451, -0.094481, -0.039238, -0.028311, 0.000136, 0.091852, -0.033647, 0.071603, -0.007952, 0.055256, -0.017529, 0.035328, 0.039685, 0.024943, -0.00095, -0.087112, -0.052553, -0.031993, 0.055766, 0.006431, 0.059345, 0.012162, 0.053177, -0.004912, -0.050763, -0.020588, -0.005488, 0.005091, -0.008583, 0.035606, 0.10337, 0.036154, 0.024719, -0.014949, -0.039329, 0.012188, 0.029272, -0.031712, 0.031482, 0.082812, -0.013747, -0.059437, -0.030512, 0.032683, 0.017726, -0.116206, 0.0, 0.001667, 0.004579, 0.05241, -0.029804, 0.00514, -0.03377, -0.06375, -0.013697, -0.056454, 0.034586, 0.080711, -0.015849, 0.023015, 0.029463, -0.054, -0.015775, 0.016155, 0.035894, -0.005101, 0.050972, 0.020428, 0.000618, 0.02292, -0.003762, 0.005427, -0.1015, 0.026604, 0.021079, -0.004396, 0.003759, -0.003281, -0.069023, -0.041193, -0.068773, -0.053672, 0.014725, 0.002872, -0.01777, 0.014501, 0.01313, -0.04992, -0.019838, 0.010573, 0.01796, 0.006464, 0.039071, -0.043627, -0.036886, -0.110046, 0.043255, -0.004958, -0.052008, -0.079468, 0.031018, 0.000946, -0.051036, -0.061875, -0.022414, -0.038451, -0.032476, -0.020249, -0.128783, -0.08277, -0.05075, -0.065273, 0.087785, 0.071226, 0.054626, -0.079816, 0.082576, -0.062877, -0.010253, -0.037195, -0.015688, -0.043611, -0.03145, 0.037785, 0.063208, 0.114132, 0.071076, 0.046347, 0.029185, 0.042234, 0.011587, -0.00499, 0.026044, -0.007527, -0.06636, 0.045405, -0.086167, -0.052291, 0.003534, 0.084929, -0.034291, -0.000695, -0.0, -0.077807, -0.053454, -0.087463, 0.043321, -0.041116, -0.070184, 0.01002, 0.01207, -0.001147, -0.016249, -0.048154, 0.07377, -0.018459, -0.040328, -0.009076, -0.040173, 0.099318, -0.051435, 0.111816, -0.089454, 0.09598, 0.033669, 0.053979, 0.073661, -0.027997, 0.031222, -0.06786, -0.01342, -0.028117, -0.024761, -0.073689, 0.033489, 0.01605, -0.007621, -0.082578, 0.109116, -0.001509, -0.036343, -0.0952, 0.085828, -0.015047, 0.080157, 0.022644, -0.06472, -0.047674, 0.017559, 0.051152, 0.033024, 0.033622, 0.064544, 0.059273, 0.019945, 0.051146, 0.103408, -0.053709, 0.041521, 0.080456, -0.016951, 0.019337, 0.117393, -0.0412, 0.086853, -0.00924, 0.051041, -0.005184, -0.062931, -0.040736, -0.134455, -0.004791, -0.094851, -0.003833, -0.081688, -0.011515, 0.03715, 0.01445, 0.100673, -0.081712, -0.025184, 0.039456, 0.049856, 0.010927, 0.027904, 0.020331, 0.119786, -0.019862, -0.003376, 0.006982, 0.016289, 0.075605, 0.003599, -0.051249, -0.054835, 0.063869, 0.013109, -0.044347, -0.0, -0.036695, -0.063979, -0.046442, -0.047263, 0.004152, -0.006187, 0.023283, 0.073998, 0.081823, 0.016833, 0.049661, 0.003787, -0.06803, 0.03604, -0.026832, 0.02872, -0.046539, 0.006037, -0.05861, -0.010851, 0.028248, 0.049821, 0.018725, 0.033924, 0.009563, 0.031509, -0.037223, 0.036996, -0.054052, 0.036899, -0.087495, 0.060992, 0.067125, -0.004534, -0.024638, 0.084441, 0.05722, 0.053871, 0.004661, 0.00211, -0.014389, -0.095461, -0.033775, -0.005752, -0.038627, -0.006197, -0.018022, 0.086152, 0.059999, -0.108308, -0.013591, 0.035795, 0.022177, 0.01406, -0.060295, -0.043534, -0.065234, -0.014292, 0.017145, -0.047879, 0.068675, -0.063154, 0.020946, -0.028792]
A12: 11 | B12: 01468167-f750-4b79-b8c8-2edf85711375 | C12: CBA.AX | D12: LGT reports 17% rise in H1 profit as assets reach record level | E12: Net new assets came in at SFr12.3bn, equal to an annualised growth rate of 6.4%. | F12: LGT reports 17% rise in H1 profit as assets reach record level - Net new assets came in at SFr12.3bn, equal to an annualised growth rate of 6.4%. | G12: [0.01093, -0.051179, -0.015799, -0.031489, 0.091158, 0.017852, 0.009322, 0.087909, -0.035465, 0.000765, -0.011281, 0.036838, -0.097592, -0.021925, -0.013414, -0.024584, -0.026689, -0.076768, -0.001885, -0.00785, 0.003269, -0.028321, 0.056583, 0.016524, 0.137591, -0.118243, -0.030675, 0.096621, 0.081288, -0.018459, 0.032146, 0.047112, 0.031309, 0.039278, -0.009714, -0.006366, -0.009213, -0.084851, -0.084731, 0.059338, 0.040624, -0.012017, -0.062889, -0.045136, -0.03014, -0.044725, 0.001439, 0.033209, -0.055971, 0.061083, 0.055382, 0.016334, 0.011309, 0.018979, -0.020544, 0.015492, -0.074366, 0.043752, 0.058077, -0.012358, -0.033705, 0.000774, 0.069809, -0.107261, 0.047985, 0.003339, 0.003276, 0.024088, -0.055094, 0.003533, -0.012534, -0.041172, -0.09022, -0.067209, -0.027278, -0.052006, 0.034279, 0.049512, 0.045073, -0.078147, 0.058631, 0.022322, -0.083687, 0.010323, -0.109963, -0.038028, 0.04522, 0.050615, -0.007178, 0.000866, -0.006854, -0.012274, -0.027339, 0.039708, -0.048585, 0.043608, -0.043449, -0.050751, 0.082773, -0.003274, -0.005408, 0.080598, 0.016566, -0.009316, -0.096607, 0.014492, 0.008341, 0.131069, 0.030807, -0.050566, 0.030159, 0.075742, -0.015988, -0.031034, -0.013627, 0.025563, -0.03829, -0.005909, 0.009786, -0.028768, 0.079193, 0.040047, 0.007323, -0.019793, -0.059899, -0.051207, -0.109925, 0.0, 0.003724, 0.029345, -0.01312, -0.018005, -0.0756, -0.025689, -0.038353, 0.07066, -0.002222, 0.010494, -0.041844, 0.03315, -0.052329, -0.073562, -0.001433, -0.072163, -0.018428, 0.016941, 0.045121, -0.033964, -0.059871, -0.014665, 0.026709, 0.009239, -0.001359, 0.022162, -0.032437, -0.03245, -0.008095, 0.00016, 0.019892, -0.033805, -0.013425, -0.013521, -0.049607, 0.007249, 0.014921, 0.016458, 0.086713, -0.034794, -0.02023, 0.084143, -0.005107, -0.044115, -0.036349, 0.050268, 0.013013, -0.01975, -0.028363, 0.069458, -0.041569, -0.017129, -0.035879, -0.075792, 0.036018, 0.033856, -0.094365, 0.024751, 0.02985, 0.057086, 0.059087, 0.06749, 0.013934, 0.084147, -0.017702, 0.03726, 0.107856, -0.012158, -0.014063, 0.037324, -0.012507, -0.030384, 0.059378, -0.032116, 0.081598, 0.004796, -0.018836, -0.026458, 0.062907, 0.072657, -0.03995, -0.000324, 0.031926, -0.078817, -0.021319, -0.016467, 0.038823, -0.10014, -0.02092, 0.058489, 0.042283, -0.101942, 0.0769, -0.009943, -0.029898, -0.0, 0.017567, 0.06061, -0.004508, -0.057021, -0.053101, 0.030816, 0.056935, -0.017859, -0.060728, 0.087112, 0.11626, 0.0196, -0.111461, -0.024275, 0.017972, -0.085971, 0.105871, -0.001252, -0.042078, -0.004655, 0.056042, 0.018023, -0.02223, 0.131168, -0.010101, 0.028138, 0.010039, 0.068797, 0.017927, -0.027062, -0.022633, -0.006456, 0.047252, -0.011788, -0.005019, -0.059683, 0.060709, -0.036097, 0.03689, -0.039172, 0.058687, -0.042756, -0.002521, -0.022641, -0.029625, -0.027377, 0.03027, -0.005868, 0.117769, 0.046866, 0.010698, 0.009792, -0.010845, -0.042076, -0.045597, 0.071393, 0.042074, 0.029571, -0.129888, 0.050403, 0.067092, 0.088031, -0.041005, 0.118602, -0.050873, -0.050842, 0.010631, -0.104301, 0.073517, -0.030514, 0.054029, 0.067056, 0.086739, -0.065546, -0.065102, -0.000695, 0.014776, -0.068152, 0.01676, -0.118349, -0.050525, 0.042951, -0.006802, -0.025591, -0.014859, -0.060761, -0.017636, 0.012875, 0.01928, 0.037892, -0.085679, -0.057141, -0.065994, 0.026346, -0.015437, -0.0, -0.049617, -0.02173, 0.009784, 0.032875, 0.019915, 0.068927, -0.015782, 0.077161, 0.012358, 0.081126, -0.020583, -0.001273, -0.031901, -0.062752, -0.033466, -0.052171, -0.007068, 0.060932, -0.034611, -0.047984, 0.085716, 0.070241, 0.082783, -0.007065, -0.031836, -0.089914, -0.03183, 0.054586, 0.047737, -0.06867, 0.082745, 0.048529, 0.048135, 0.030404, 0.0804, -0.011493, 0.02478, 0.088748, -0.006354, 0.005977, 0.018809, 0.020478, -0.011532, -0.010049, -0.072172, -0.023348, -0.110613, -0.026401, 0.020543, -0.152194, 0.112778, 0.019734, -0.028122, -0.011621, 0.036551, 0.036448, -0.018719, 0.012663, -0.048859, -0.036995, 0.011178, -0.096649, -0.009861, 0.056938]
A13: 12 | B13: 5471b7ec-a7a3-4b6f-9ed9-1077daa933df | C13: CBA.AX | D13: Fast Money Bets on November RBA Hike in Fight Against Inflation | E13: Speculative investors are increasingly betting the Reserve Bank of Australia will raise interest rates again in November as inflation remains above the central bank’s target. | F13: Fast Money Bets on November RBA Hike in Fight Against Inflation - Speculative investors are increasingly betting the Reserve Bank of Australia will raise interest rates again in November as inflation remains above the central bank’s target. | G13: [-0.071025, -0.079204, -0.120371, 0.079145, -0.018242, 0.006971, -0.036173, 0.008664, 0.002778, 0.006519, -0.047016, 0.053294, -0.037991, 0.00609, 0.050269, 0.016932, 0.016307, -0.014505, -0.007567, 0.019713, -0.046585, -0.07531, -0.058002, 0.02604, 0.097024, -0.0357, 0.06472, -0.001252, -0.055762, -0.028225, 0.019501, 0.023328, 0.043446, -0.063793, 0.033321, -0.018996, -0.028198, -0.010309, -0.005334, 0.054666, 0.061665, -0.014863, -0.00453, 0.001674, -0.000343, -0.007796, 0.044016, 0.084705, -0.020393, 0.043307, 0.013772, -0.024261, -0.030923, -0.052592, -0.018958, 0.011816, -0.001785, 0.004654, 0.117353, -0.042586, 0.044202, -0.011933, 0.004191, -0.025825, 0.001773, -0.059696, -0.048843, 0.042665, 0.030482, 0.007738, 0.041983, 0.000579, -0.02913, -0.14002, 0.00409, -0.0251, 0.018707, -0.006651, 0.035711, -0.042389, 0.022167, -0.075997, 0.030536, -0.104988, -0.008978, 0.050232, 0.123078, -0.046696, 0.014683, -0.039494, 0.086211, 0.001221, 0.030895, -0.026795, 0.002128, -0.02556, -0.007441, -0.11916, -0.000948, 0.040309, 0.074722, 0.004096, -0.039311, 0.073913, 0.050252, -0.018647, -0.043078, 0.027828, 0.013302, 3.9e-05, -0.013339, 0.111014, 0.092219, 0.022506, -0.111602, 0.029962, -0.058504, -0.021054, 0.012036, 0.08821, 0.047855, 0.056156, 0.008042, -0.036787, 0.048462, 0.024335, -0.065045, 0.0, 0.037707, 0.037601, -0.005677, -0.097219, -0.028464, 0.033879, -0.060809, -0.005597, -0.022704, 0.000252, 0.001801, 0.058133, 0.02348, 0.030998, -0.05364, -0.065233, 0.005043, 0.036185, 0.080557, 0.041871, 0.020515, -0.063018, 0.013376, -0.069951, -0.012594, -0.01723, 0.072114, -0.057171, 0.059542, 0.014296, -0.01786, 0.063097, -0.053664, -0.075956, -0.06189, 0.000187, 0.012077, -0.055354, -0.06903, -0.011956, 0.014101, 0.04423, -0.001922, 0.024728, -0.028606, 0.050912, -0.009126, -0.029239, -0.042063, 0.046193, -0.023575, -0.043514, -0.043908, 0.033149, 0.035597, -0.086668, -0.035035, -0.030596, 0.043314, -0.045831, 0.046746, -0.026681, -0.095748, -0.022451, -0.138791, 0.032718, -0.002582, -0.00517, -0.08844, 0.041995, 0.003054, 0.037312, 0.036501, -0.011614, -0.065845, -0.076264, 0.067584, 0.028736, 0.052106, -0.040087, 0.027272, 0.002572, 0.060307, -0.034053, 0.03262, -0.007009, -0.040427, -0.101456, 0.011014, -0.135657, -0.081435, -0.053062, 0.04781, -0.020622, 0.044462, -0.0, 0.025039, -0.058286, 0.050295, 0.132023, 0.042469, -0.074595, 0.022079, -0.015519, 0.090561, -0.011386, -0.092763, 0.070289, 0.035365, 0.087517, 0.112134, -0.092508, 0.039307, -0.01543, 0.046863, -0.04414, -0.031991, -0.026659, -0.02685, 0.085065, -0.000736, -0.066666, -0.007203, 0.00026, -0.064847, -0.008996, -0.046858, 0.032634, -0.022873, -0.041706, -0.093934, 0.054455, 0.028615, 0.024492, -0.02473, 0.027315, 0.055783, 0.000625, -0.014568, -0.039795, 0.002662, 0.006249, 0.055171, 0.118873, 0.041417, 0.095981, 0.009227, -0.077542, -0.006207, 0.072391, -0.006337, -0.018861, 0.004101, -0.001116, -0.008185, 0.068968, 0.025274, 0.056422, 0.04618, 0.032426, 0.024686, 0.000251, 0.000932, -0.048501, 0.102436, 0.038788, 0.050999, 0.037518, -0.042972, 0.092703, 0.033878, 0.034878, -0.018513, 0.006352, 0.062129, 0.030197, -0.01416, 0.003975, 0.011128, -0.005639, 0.006286, 0.051692, 0.021931, -0.042548, -0.000468, -0.036036, -0.055424, -0.073936, 0.146121, 0.037606, -0.07086, -0.0, -0.025233, -0.04898, -0.006152, 0.030836, 0.047348, 0.028804, 0.013325, -0.00299, 0.032388, -0.011438, 0.058125, 0.025495, -0.019323, -0.073913, 0.015084, 0.081033, -0.009137, -0.001107, -0.031372, 0.005443, 0.083685, 0.135217, 0.046903, -0.038795, -0.001636, -0.039462, 0.010736, 0.124971, -0.015822, 0.003362, -0.036969, 0.03039, 0.053682, -0.013788, 0.000354, -0.00352, 0.084115, 0.143978, 0.025746, -0.005276, 0.036275, -0.081654, -0.038761, -0.103284, -0.072362, -0.045735, -0.036644, -0.064014, 0.024976, -0.068386, -0.02152, 0.003597, -0.00215, 0.08617, 0.057648, -0.023861, -0.068769, -0.033452, 0.017424, 0.009379, -0.038838, -0.171085, -0.021411, 0.007146]
